#VRML_SIM R2025a utf8

EXTERNPROTO "https://raw.githubusercontent.com/cyberbotics/webots/R2025a/projects/objects/backgrounds/protos/TexturedBackground.proto"
EXTERNPROTO "https://raw.githubusercontent.com/cyberbotics/webots/R2025a/projects/objects/backgrounds/protos/TexturedBackgroundLight.proto"
EXTERNPROTO "https://raw.githubusercontent.com/cyberbotics/webots/R2025a/projects/objects/factory/containers/protos/WoodenBox.proto"
EXTERNPROTO "https://raw.githubusercontent.com/cyberbotics/webots/R2025a/projects/robots/gctronic/e-puck/protos/E-puck.proto"
EXTERNPROTO "https://raw.githubusercontent.com/cyberbotics/webots/R2025a/projects/objects/floors/protos/Floor.proto"
EXTERNPROTO "https://raw.githubusercontent.com/cyberbotics/webots/R2025a/projects/appearances/protos/OldSteel.proto"
EXTERNPROTO "https://raw.githubusercontent.com/cyberbotics/webots/R2025a/projects/appearances/protos/Parquetry.proto"
EXTERNPROTO "../protos/FourWheelsRobot.proto"

WorldInfo {
  info [
    "Primera simulación en la cual estan los conceptos basicos aprendidos en el tutorial, usa para ejemplo y futuras referencias"
  ]
  basicTimeStep 16
  contactProperties [
    ContactProperties {
    }
  ]
}
Viewpoint {
  orientation 0.21165783504130173 -0.10049856456717368 -0.9721630518516772 4.006506553080809
  position 0.8476962843308096 -0.89656757369379 0.7176468224507974
}
TexturedBackground {
  texture "twilight_cloudy_empty"
}
TexturedBackgroundLight {
}
Floor {
  size 1 1
  appearance Parquetry {
    type "light strip"
  }
}
Solid {
  translation -0.14 -0.3 0.05
  children [
    Shape {
      appearance OldSteel {
      }
      geometry DEF BALL_GEOMETRY Sphere {
        radius 0.05
        subdivision 2
      }
    }
  ]
  name "sphere_1"
  boundingObject USE BALL_GEOMETRY
  physics Physics {
  }
}
E-puck {
  controller "EPuckAvoidController"
}
DEF BOX_1 WoodenBox {
  translation -0.281369 0.312631 0.12
  rotation 0 0 1 2.618
  name ""
  size 0.1 0.1 0.1
  mass 0.4
}
Solid {
  translation 0 0.25 0.11
  children [
    Shape {
      appearance PBRAppearance {
        baseColor 1 0.5 1
        baseColorMap ImageTexture {
          url [
            "../../../Downloads/red_brick_wall.jpg"
          ]
        }
        roughness 1
        metalness 0
      }
      geometry DEF SPHERE_GEO Sphere {
        radius 0.05
        subdivision 2
      }
    }
  ]
  name "sphere_2"
  boundingObject USE SPHERE_GEO
  physics Physics {
  }
}
Solid {
  translation 0.55 0 0.1
  children [
    DEF WALL Shape {
      appearance PBRAppearance {
        baseColor 0.2 0.6 1
        roughness 1
        metalness 0
      }
      geometry Box {
        size 0.1 1 0.2
      }
    }
  ]
  name "Wall_1"
  boundingObject USE WALL
}
Solid {
  translation -0.55 0 0.1
  children [
    USE WALL
  ]
  name "Wall_2"
  boundingObject USE WALL
}
Solid {
  translation 3.67306e-06 0.55 0.1
  rotation 0 0 1 1.5708
  children [
    USE WALL
  ]
  name "Wall_3"
  boundingObject USE WALL
}
Solid {
  translation -3.67306e-06 -0.55 0.1
  rotation 0 0 1 1.5708
  children [
    USE WALL
  ]
  name "Wall_4"
  boundingObject USE WALL
}
DEF MANCUERNA Solid {
  translation -0.339999 0 0.08
  rotation 0 1 0 1.5708
  children [
    DEF G0 Group {
      children [
        Pose {
          translation 0 0 -0.07
          children [
            Shape {
              appearance PBRAppearance {
              }
              geometry Sphere {
                radius 0.03
                subdivision 2
              }
            }
          ]
        }
        Shape {
          appearance PBRAppearance {
          }
          geometry Cylinder {
            height 0.1
            radius 0.01
          }
        }
        Pose {
          translation 0 0 0.07
          children [
            Shape {
              appearance PBRAppearance {
              }
              geometry Sphere {
                radius 0.03
                subdivision 2
              }
            }
          ]
        }
      ]
    }
  ]
  contactMaterial ""
  boundingObject USE G0
  physics Physics {
    density -1
    mass 2
    centerOfMass [
      0 0 0.01
    ]
  }
}
Robot {
  translation 0.21 -0.22 0.05
  children [
    DEF BODY Shape {
      appearance PBRAppearance {
        baseColor 0.4 0.8 1
        roughness 1
        metalness 0
      }
      geometry Box {
        size 0.2 0.1 0.05
      }
    }
    DEF WHEEL1 HingeJoint {
      jointParameters HingeJointParameters {
        axis 0 1 0
        anchor 0.05 0.06 0
      }
      device [
        RotationalMotor {
          name "wheel1"
        }
      ]
      endPoint Solid {
        translation 0.05 0.06 0
        rotation 1 0 0 1.57
        children [
          DEF WHEEL Shape {
            appearance PBRAppearance {
            }
            geometry Cylinder {
              height 0.02
              radius 0.04
              subdivision 24
            }
          }
        ]
        boundingObject USE WHEEL
        physics Physics {
        }
      }
    }
    DEF WHEEL2 HingeJoint {
      jointParameters HingeJointParameters {
        axis 0 1 0
        anchor 0.05 -0.06 0
      }
      device [
        RotationalMotor {
          name "wheel2"
        }
      ]
      endPoint Solid {
        translation 0.05 -0.06 0
        rotation 1 0 0 1.57
        children [
          USE WHEEL
        ]
        name "solid(1)"
        boundingObject USE WHEEL
        physics Physics {
        }
      }
    }
    DEF WHEEL3 HingeJoint {
      jointParameters HingeJointParameters {
        axis 0 1 0
        anchor -0.05 0.06 0
      }
      device [
        RotationalMotor {
          name "wheel3"
        }
      ]
      endPoint Solid {
        translation -0.05 0.06 0
        rotation 1 0 0 1.57
        children [
          USE WHEEL
        ]
        name "solid(2)"
        boundingObject USE WHEEL
        physics Physics {
        }
      }
    }
    DEF WHEEL4 HingeJoint {
      jointParameters HingeJointParameters {
        axis 0 1 0
        anchor -0.05 -0.06 0
      }
      device [
        RotationalMotor {
          name "wheel4"
        }
      ]
      endPoint Solid {
        translation -0.05 -0.06 0
        rotation 1 0 0 1.57
        children [
          USE WHEEL
        ]
        name "solid(3)"
        boundingObject USE WHEEL
        physics Physics {
        }
      }
    }
    DEF DS_RIGHT DistanceSensor {
      translation 0.1 -0.03 0
      rotation 0 0 1 -0.3
      children [
        Shape {
          appearance PBRAppearance {
            roughness 1
            metalness 0
          }
          geometry Box {
            size 0.01 0.01 0.01
          }
        }
      ]
      name "ds_right"
    }
    DEF DS_LEFT DistanceSensor {
      translation 0.1 0.03 0
      rotation 0 0 1 0.3
      children [
        Shape {
          appearance PBRAppearance {
          }
          geometry Box {
            size 0.01 0.01 0.01
          }
        }
      ]
      name "ds_left"
    }
  ]
  boundingObject USE BODY
  physics Physics {
  }
  controller "four_wheeled_collision_avoidance"
}
FourWheelsRobot {
  translation 0.22 0.23 0.07
}
